<?xml version="1.0"?>
<sdf version="1.6">
  <world name="default">
    <!-- Light source -->
    <light type="directional" name="sun">
      <cast_shadows>true</cast_shadows>
      <pose>0 0 10 0 0 0</pose>
      <diffuse>0.8 0.8 0.8 1</diffuse>
      <specular>0.2 0.2 0.2 1</specular>
      <attenuation>
        <range>1000</range>
        <constant>0.9</constant>
        <linear>0.01</linear>
        <quadratic>0.001</quadratic>
      </attenuation>
      <direction>-0.5 0.1 -0.9</direction>
    </light>

    <!-- Ground plane -->
    <model name="ground_plane">
      <static>true</static>
      <link name="link">
        <collision name="collision">
          <geometry>
            <plane>
              <normal>0 0 1</normal>
              <size>100 100</size>
            </plane>
          </geometry>
        </collision>
        <visual name="visual">
          <geometry>
            <plane>
              <normal>0 0 1</normal>
              <size>100 100</size>
            </plane>
          </geometry>
          <material>
            <ambient>0.8 0.8 0.8 1</ambient>
            <diffuse>0.8 0.8 0.8 1</diffuse>
            <specular>0.8 0.8 0.8 1</specular>
          </material>
        </visual>
      </link>
    </model>
    
    <!-- TurtleBot3 with depth camera -->
    <model name="turtlebot3_waffle">
      <static>false</static>
      <pose>0 0 0.01 0 0 0</pose>
      
      <!-- Base link -->
      <link name="base_link">
        <inertial>
          <mass>1.0</mass>
          <inertia>
            <ixx>0.001</ixx>
            <iyy>0.001</iyy>
            <izz>0.001</izz>
          </inertia>
        </inertial>
        
        <!-- Base visual -->
        <visual name="base_visual">
          <geometry>
            <box>
              <size>0.178 0.156 0.077</size>
            </box>
          </geometry>
          <material>
            <ambient>0.0 0.0 0.0 1.0</ambient>
            <diffuse>0.0 0.0 0.0 1.0</diffuse>
            <specular>0.0 0.0 0.0 1.0</specular>
          </material>
        </visual>
        
        <!-- Base collision -->
        <collision name="base_collision">
          <geometry>
            <box>
              <size>0.178 0.156 0.077</size>
            </box>
          </geometry>
        </collision>
        
        <!-- Depth camera -->
        <sensor name="depth_camera" type="depth">
          <pose>0.073 0 0.084 0 0 0</pose>
          <camera>
            <horizontal_fov>1.02974</horizontal_fov>
            <image>
              <width>640</width>
              <height>480</height>
              <format>R8G8B8</format>
            </image>
            <clip>
              <near>0.1</near>
              <far>10</far>
            </clip>
          </camera>
          <always_on>1</always_on>
          <update_rate>10</update_rate>
          <visualize>true</visualize>
          <plugin
            filename="libignition-gazebo-sensors-system.so"
            name="ignition::gazebo::systems::Sensors">
            <render_engine>ogre2</render_engine>
          </plugin>
        </sensor>
        
        <!-- LiDAR sensor -->
        <sensor name="lidar" type="lidar">
          <pose>0 0 0.15 0 0 0</pose>
          <lidar>
            <scan>
              <horizontal>
                <samples>360</samples>
                <resolution>1</resolution>
                <min_angle>-3.14159</min_angle>
                <max_angle>3.14159</max_angle>
              </horizontal>
            </scan>
            <range>
              <min>0.12</min>
              <max>3.5</max>
              <resolution>0.015</resolution>
            </range>
          </lidar>
          <always_on>1</always_on>
          <update_rate>10</update_rate>
          <visualize>true</visualize>
          <plugin
            filename="libignition-gazebo-sensors-system.so"
            name="ignition::gazebo::systems::Sensors">
            <render_engine>ogre2</render_engine>
          </plugin>
        </sensor>
      </link>
      
      <!-- Left wheel -->
      <link name="left_wheel">
        <pose>0 0.08 0.033 -1.5707 0 0</pose>
        <inertial>
          <mass>0.1</mass>
          <inertia>
            <ixx>0.001</ixx>
            <iyy>0.001</iyy>
            <izz>0.001</izz>
          </inertia>
        </inertial>
        
        <visual name="left_wheel_visual">
          <geometry>
            <cylinder>
              <radius>0.033</radius>
              <length>0.018</length>
            </cylinder>
          </geometry>
          <material>
            <ambient>0.2 0.2 0.2 1.0</ambient>
            <diffuse>0.2 0.2 0.2 1.0</diffuse>
          </material>
        </visual>
        
        <collision name="left_wheel_collision">
          <geometry>
            <cylinder>
              <radius>0.033</radius>
              <length>0.018</length>
            </cylinder>
          </geometry>
        </collision>
      </link>
      
      <!-- Right wheel -->
      <link name="right_wheel">
        <pose>0 -0.08 0.033 -1.5707 0 0</pose>
        <inertial>
          <mass>0.1</mass>
          <inertia>
            <ixx>0.001</ixx>
            <iyy>0.001</iyy>
            <izz>0.001</izz>
          </inertia>
        </inertial>
        
        <visual name="right_wheel_visual">
          <geometry>
            <cylinder>
              <radius>0.033</radius>
              <length>0.018</length>
            </cylinder>
          </geometry>
          <material>
            <ambient>0.2 0.2 0.2 1.0</ambient>
            <diffuse>0.2 0.2 0.2 1.0</diffuse>
          </material>
        </visual>
        
        <collision name="right_wheel_collision">
          <geometry>
            <cylinder>
              <radius>0.033</radius>
              <length>0.018</length>
            </cylinder>
          </geometry>
        </collision>
      </link>
      
      <!-- Left wheel joint -->
      <joint name="left_wheel_joint" type="revolute">
        <parent>base_link</parent>
        <child>left_wheel</child>
        <axis>
          <xyz>0 0 1</xyz>
        </axis>
      </joint>
      
      <!-- Right wheel joint -->
      <joint name="right_wheel_joint" type="revolute">
        <parent>base_link</parent>
        <child>right_wheel</child>
        <axis>
          <xyz>0 0 1</xyz>
        </axis>
      </joint>
      
      <!-- Differential drive plugin -->
      <plugin
        filename="libignition-gazebo-diff-drive-system.so"
        name="ignition::gazebo::systems::DiffDrive">
        <left_joint>left_wheel_joint</left_joint>
        <right_joint>right_wheel_joint</right_joint>
        <wheel_separation>0.16</wheel_separation>
        <wheel_radius>0.033</wheel_radius>
        <odom_publish_frequency>30</odom_publish_frequency>
        <topic>/cmd_vel</topic>
        <odom_topic>/odom</odom_topic>
        <frame_id>odom</frame_id>
        <child_frame_id>base_link</child_frame_id>
      </plugin>
    </model>
    
    <!-- Simple obstacles for navigation -->
    <model name="obstacle1">
      <static>true</static>
      <pose>2 0 0.5 0 0 0</pose>
      <link name="link">
        <visual name="visual">
          <geometry>
            <box>
              <size>0.5 0.5 1</size>
            </box>
          </geometry>
          <material>
            <ambient>0.8 0.2 0.2 1</ambient>
            <diffuse>0.8 0.2 0.2 1</diffuse>
          </material>
        </visual>
        <collision name="collision">
          <geometry>
            <box>
              <size>0.5 0.5 1</size>
            </box>
          </geometry>
        </collision>
      </link>
    </model>
    
    <model name="obstacle2">
      <static>true</static>
      <pose>-2 1.5 0.5 0 0 0</pose>
      <link name="link">
        <visual name="visual">
          <geometry>
            <box>
              <size>0.5 0.5 1</size>
            </box>
          </geometry>
          <material>
            <ambient>0.2 0.8 0.2 1</ambient>
            <diffuse>0.2 0.8 0.2 1</diffuse>
          </material>
        </visual>
        <collision name="collision">
          <geometry>
            <box>
              <size>0.5 0.5 1</size>
            </box>
          </geometry>
        </collision>
      </link>
    </model>
    
    <!-- Physics settings -->
    <physics name="default_physics" default="0" type="ode">
      <gravity>0 0 -9.8066</gravity>
      <ode>
        <solver>
          <type>quick</type>
          <iters>150</iters>
          <sor>1.3</sor>
        </solver>
        <constraints>
          <cfm>0.00001</cfm>
          <erp>0.2</erp>
          <contact_max_correcting_vel>1000</contact_max_correcting_vel>
          <contact_surface_layer>0.01</contact_surface_layer>
        </constraints>
      </ode>
      <max_step_size>0.004</max_step_size>
      <real_time_factor>1.0</real_time_factor>
      <real_time_update_rate>250</real_time_update_rate>
    </physics>
  </world>
</sdf>